Workbook

Sheet Top 100 Ragas
A1: Rank | B1: Raga | C1: Type | D1: Melakarta no. (own / parent) | E1: Parent melakarta | F1: Arohanam | G1: Avarohanam | H1: Swaras in arohanam | I1: Swaras in avarohanam | J1: Arohanam class | K1: Avarohanam class | L1: Raga class | M1: Vakra? | N1: Usage band | O1: Scale source | P1: Confidence | Q1: Notes / flags | R1: Row no. in your sheet | S1: Expert verified?
A2: 1 | B2: Mayamalavagowla | C2: Melakarta | D2: 15 | E2: (is a melakarta) | F2: S R1 G3 M1 P D1 N3 S' | G2: S' N3 D1 P M1 G3 R1 S | H2: =1+ISNUMBER(SEARCH("R",F2))+ISNUMBER(SEARCH("G",F2))+ISNUMBER(SEARCH("M",F2))+ISNUMBER(SEARCH("P",F2))+ISNUMBER(SEARCH("D",F2))+ISNUMBER(SEARCH("N",F2)) -> 7 | I2: =1+ISNUMBER(SEARCH("R",G2))+ISNUMBER(SEARCH("G",G2))+ISNUMBER(SEARCH("M",G2))+ISNUMBER(SEARCH("P",G2))+ISNUMBER(SEARCH("D",G2))+ISNUMBER(SEARCH("N",G2)) -> 7 | J2: =IFERROR(CHOOSE(H2-3,"Svarantara","Audava","Shadava","Sampoorna"),"Other") -> Sampoorna | K2: =IFERROR(CHOOSE(I2-3,"Svarantara","Audava","Shadava","Sampoorna"),"Other") -> Sampoorna | L2: =J2&" - "&K2 -> Sampoorna - Sampoorna | M2: No | N2: A - Very common | O2: Your sheet (systematic) | P2: High | Q2: Mayamalavagowla | R2: 15
A3: 2 | B3: Mechakalyani | C3: Melakarta | D3: 65 | E3: (is a melakarta) | F3: S R2 G3 M2 P D2 N3 S' | G3: S' N3 D2 P M2 G3 R2 S | H3: =1+ISNUMBER(SEARCH("R",F3))+ISNUMBER(SEARCH("G",F3))+ISNUMBER(SEARCH("M",F3))+ISNUMBER(SEARCH("P",F3))+ISNUMBER(SEARCH("D",F3))+ISNUMBER(SEARCH("N",F3)) -> 7 | I3: =1+ISNUMBER(SEARCH("R",G3))+ISNUMBER(SEARCH("G",G3))+ISNUMBER(SEARCH("M",G3))+ISNUMBER(SEARCH("P",G3))+ISNUMBER(SEARCH("D",G3))+ISNUMBER(SEARCH("N",G3)) -> 7 | J3: =IFERROR(CHOOSE(H3-3,"Svarantara","Audava","Shadava","Sampoorna"),"Other") -> Sampoorna | K3: =IFERROR(CHOOSE(I3-3,"Svarantara","Audava","Shadava","Sampoorna"),"Other") -> Sampoorna | L3: =J3&" - "&K3 -> Sampoorna - Sampoorna | M3: No | N3: A - Very common | O3: Your sheet (systematic) | P3: High | Q3: Kalyani | R3: 65
A4: 3 | B4: Dheerasankarabharanam | C4: Melakarta | D4: 29 | E4: (is a melakarta) | F4: S R2 G3 M1 P D2 N3 S' | G4: S' N3 D2 P M1 G3 R2 S | H4: =1+ISNUMBER(SEARCH("R",F4))+ISNUMBER(SEARCH("G",F4))+ISNUMBER(SEARCH("M",F4))+ISNUMBER(SEARCH("P",F4))+ISNUMBER(SEARCH("D",F4))+ISNUMBER(SEARCH("N",F4)) -> 7 | I4: =1+ISNUMBER(SEARCH("R",G4))+ISNUMBER(SEARCH("G",G4))+ISNUMBER(SEARCH("M",G4))+ISNUMBER(SEARCH("P",G4))+ISNUMBER(SEARCH("D",G4))+ISNUMBER(SEARCH("N",G4)) -> 7 | J4: =IFERROR(CHOOSE(H4-3,"Svarantara","Audava","Shadava","Sampoorna"),"Other") -> Sampoorna | K4: =IFERROR(CHOOSE(I4-3,"Svarantara","Audava","Shadava","Sampoorna"),"Other") -> Sampoorna | L4: =J4&" - "&K4 -> Sampoorna - Sampoorna | M4: No | N4: A - Very common | O4: Your sheet (systematic) | P4: High | Q4: Sankarabharanam | R4: 29
A5: 4 | B5: Kharaharapriya | C5: Melakarta | D5: 22 | E5: (is a melakarta) | F5: S R2 G2 M1 P D2 N2 S' | G5: S' N2 D2 P M1 G2 R2 S | H5: =1+ISNUMBER(SEARCH("R",F5))+ISNUMBER(SEARCH("G",F5))+ISNUMBER(SEARCH("M",F5))+ISNUMBER(SEARCH("P",F5))+ISNUMBER(SEARCH("D",F5))+ISNUMBER(SEARCH("N",F5)) -> 7 | I5: =1+ISNUMBER(SEARCH("R",G5))+ISNUMBER(SEARCH("G",G5))+ISNUMBER(SEARCH("M",G5))+ISNUMBER(SEARCH("P",G5))+ISNUMBER(SEARCH("D",G5))+ISNUMBER(SEARCH("N",G5)) -> 7 | J5: =IFERROR(CHOOSE(H5-3,"Svarantara","Audava","Shadava","Sampoorna"),"Other") -> Sampoorna | K5: =IFERROR(CHOOSE(I5-3,"Svarantara","Audava","Shadava","Sampoorna"),"Other") -> Sampoorna | L5: =J5&" - "&K5 -> Sampoorna - Sampoorna | M5: No | N5: A - Very common | O5: Your sheet (systematic) | P5: High | Q5: Kharaharapriya | R5: 22
A6: 5 | B6: Hanumatodi | C6: Melakarta | D6: 8 | E6: (is a melakarta) | F6: S R1 G2 M1 P D1 N2 S' | G6: S' N2 D1 P M1 G2 R1 S | H6: =1+ISNUMBER(SEARCH("R",F6))+ISNUMBER(SEARCH("G",F6))+ISNUMBER(SEARCH("M",F6))+ISNUMBER(SEARCH("P",F6))+ISNUMBER(SEARCH("D",F6))+ISNUMBER(SEARCH("N",F6)) -> 7 | I6: =1+ISNUMBER(SEARCH("R",G6))+ISNUMBER(SEARCH("G",G6))+ISNUMBER(SEARCH("M",G6))+ISNUMBER(SEARCH("P",G6))+ISNUMBER(SEARCH("D",G6))+ISNUMBER(SEARCH("N",G6)) -> 7 | J6: =IFERROR(CHOOSE(H6-3,"Svarantara","Audava","Shadava","Sampoorna"),"Other") -> Sampoorna | K6: =IFERROR(CHOOSE(I6-3,"Svarantara","Audava","Shadava","Sampoorna"),"Other") -> Sampoorna | L6: =J6&" - "&K6 -> Sampoorna - Sampoorna | M6: No | N6: A - Very common | O6: Your sheet (systematic) | P6: High | Q6: Todi | R6: 8
A7: 6 | B7: Harikambhoji | C7: Melakarta | D7: 28 | E7: (is a melakarta) | F7: S R2 G3 M1 P D2 N2 S' | G7: S' N2 D2 P M1 G3 R2 S | H7: =1+ISNUMBER(SEARCH("R",F7))+ISNUMBER(SEARCH("G",F7))+ISNUMBER(SEARCH("M",F7))+ISNUMBER(SEARCH("P",F7))+ISNUMBER(SEARCH("D",F7))+ISNUMBER(SEARCH("N",F7)) -> 7 | I7: =1+ISNUMBER(SEARCH("R",G7))+ISNUMBER(SEARCH("G",G7))+ISNUMBER(SEARCH("M",G7))+ISNUMBER(SEARCH("P",G7))+ISNUMBER(SEARCH("D",G7))+ISNUMBER(SEARCH("N",G7)) -> 7 | J7: =IFERROR(CHOOSE(H7-3,"Svarantara","Audava","Shadava","Sampoorna"),"Other") -> Sampoorna | K7: =IFERROR(CHOOSE(I7-3,"Svarantara","Audava","Shadava","Sampoorna"),"Other") -> Sampoorna | L7: =J7&" - "&K7 -> Sampoorna - Sampoorna | M7: No | N7: A - Very common | O7: Your sheet (systematic) | P7: High | Q7: Kambhoji family parent | R7: 28
A8: 7 | B8: Bhairavi | C8: Janya | D8: 20 | E8: 20 - Natabhairavi | F8: S R2 G2 M1 P D1 N2 S' | G8: S' N2 D1 P M1 G2 R2 S | H8: =1+ISNUMBER(SEARCH("R",F8))+ISNUMBER(SEARCH("G",F8))+ISNUMBER(SEARCH("M",F8))+ISNUMBER(SEARCH("P",F8))+ISNUMBER(SEARCH("D",F8))+ISNUMBER(SEARCH("N",F8)) -> 7 | I8: =1+ISNUMBER(SEARCH("R",G8))+ISNUMBER(SEARCH("G",G8))+ISNUMBER(SEARCH("M",G8))+ISNUMBER(SEARCH("P",G8))+ISNUMBER(SEARCH("D",G8))+ISNUMBER(SEARCH("N",G8)) -> 7 | J8: =IFERROR(CHOOSE(H8-3,"Svarantara","Audava","Shadava","Sampoorna"),"Other") -> Sampoorna | K8: =IFERROR(CHOOSE(I8-3,"Svarantara","Audava","Shadava","Sampoorna"),"Other") -> Sampoorna | L8: =J8&" - "&K8 -> Sampoorna - Sampoorna | M8: No | N8: A - Very common | O8: Your sheet | P8: High | Q8: Your sheet gives the plain Natabhairavi scale. In practice it is sung vakra (S G2 R2 G2 M1 P D1 N2 S') and bhashanga. Class is unchanged. | R8: 100
A9: 8 | B9: Mohanam | C9: Janya | D9: 28 | E9: 28 - Harikambhoji | F9: S R2 G3 P D2 S' | G9: S' D2 P G3 R2 S | H9: =1+ISNUMBER(SEARCH("R",F9))+ISNUMBER(SEARCH("G",F9))+ISNUMBER(SEARCH("M",F9))+ISNUMBER(SEARCH("P",F9))+ISNUMBER(SEARCH("D",F9))+ISNUMBER(SEARCH("N",F9)) -> 5 | I9: =1+ISNUMBER(SEARCH("R",G9))+ISNUMBER(SEARCH("G",G9))+ISNUMBER(SEARCH("M",G9))+ISNUMBER(SEARCH("P",G9))+ISNUMBER(SEARCH("D",G9))+ISNUMBER(SEARCH("N",G9)) -> 5 | J9: =IFERROR(CHOOSE(H9-3,"Svarantara","Audava","Shadava","Sampoorna"),"Other") -> Audava | K9: =IFERROR(CHOOSE(I9-3,"Svarantara","Audava","Shadava","Sampoorna"),"Other") -> Audava | L9: =J9&" - "&K9 -> Audava - Audava | M9: No | N9: A - Very common | O9: Your sheet | P9: High | R9: 134
A10: 9 | B10: Kambhoji | C10: Janya | D10: 28 | E10: 28 - Harikambhoji | F10: S R2 G3 M1 P D2 S' | G10: S' N2 D2 P M1 G3 R2 S | H10: =1+ISNUMBER(SEARCH("R",F10))+ISNUMBER(SEARCH("G",F10))+ISNUMBER(SEARCH("M",F10))+ISNUMBER(SEARCH("P",F10))+ISNUMBER(SEARCH("D",F10))+ISNUMBER(SEARCH("N",F10)) -> 6 | I10: =1+ISNUMBER(SEARCH("R",G10))+ISNUMBER(SEARCH("G",G10))+ISNUMBER(SEARCH("M",G10))+ISNUMBER(SEARCH("P",G10))+ISNUMBER(SEARCH("D",G10))+ISNUMBER(SEARCH("N",G10)) -> 7 | J10: =IFERROR(CHOOSE(H10-3,"Svarantara","Audava","Shadava","Sampoorna"),"Other") -> Shadava | K10: =IFERROR(CHOOSE(I10-3,"Svarantara","Audava","Shadava","Sampoorna"),"Other") -> Sampoorna | L10: =J10&" - "&K10 -> Shadava - Sampoorna | M10: No | N10: A - Very common | O10: Your sheet | P10: High | Q10: Bhashanga (N3 anya swara) and vakra phrases in practice. | R10: 123
A11: 10 | B11: Shanmukhapriya | C11: Melakarta | D11: 56 | E11: (is a melakarta) | F11: S R2 G2 M2 P D1 N2 S' | G11: S' N2 D1 P M2 G2 R2 S | H11: =1+ISNUMBER(SEARCH("R",F11))+ISNUMBER(SEARCH("G",F11))+ISNUMBER(SEARCH("M",F11))+ISNUMBER(SEARCH("P",F11))+ISNUMBER(SEARCH("D",F11))+ISNUMBER(SEARCH("N",F11)) -> 7 | I11: =1+ISNUMBER(SEARCH("R",G11))+ISNUMBER(SEARCH("G",G11))+ISNUMBER(SEARCH("M",G11))+ISNUMBER(SEARCH("P",G11))+ISNUMBER(SEARCH("D",G11))+ISNUMBER(SEARCH("N",G11)) -> 7 | J11: =IFERROR(CHOOSE(H11-3,"Svarantara","Audava","Shadava","Sampoorna"),"Other") -> Sampoorna | K11: =IFERROR(CHOOSE(I11-3,"Svarantara","Audava","Shadava","Sampoorna"),"Other") -> Sampoorna | L11: =J11&" - "&K11 -> Sampoorna - Sampoorna | M11: No | N11: A - Very common | O11: Your sheet (systematic) | P11: High | Q11: Shanmukhapriya | R11: 56
A12: 11 | B12: Charukesi | C12: Melakarta | D12: 26 | E12: (is a melakarta) | F12: S R2 G3 M1 P D1 N2 S' | G12: S' N2 D1 P M1 G3 R2 S | H12: =1+ISNUMBER(SEARCH("R",F12))+ISNUMBER(SEARCH("G",F12))+ISNUMBER(SEARCH("M",F12))+ISNUMBER(SEARCH("P",F12))+ISNUMBER(SEARCH("D",F12))+ISNUMBER(SEARCH("N",F12)) -> 7 | I12: =1+ISNUMBER(SEARCH("R",G12))+ISNUMBER(SEARCH("G",G12))+ISNUMBER(SEARCH("M",G12))+ISNUMBER(SEARCH("P",G12))+ISNUMBER(SEARCH("D",G12))+ISNUMBER(SEARCH("N",G12)) -> 7 | J12: =IFERROR(CHOOSE(H12-3,"Svarantara","Audava","Shadava","Sampoorna"),"Other") -> Sampoorna | K12: =IFERROR(CHOOSE(I12-3,"Svarantara","Audava","Shadava","Sampoorna"),"Other") -> Sampoorna | L12: =J12&" - "&K12 -> Sampoorna - Sampoorna | M12: No | N12: A - Very common | O12: Your sheet (systematic) | P12: High | Q12: Charukesi | R12: 26
A13: 12 | B13: Natabhairavi | C13: Melakarta | D13: 20 | E13: (is a melakarta) | F13: S R2 G2 M1 P D1 N2 S' | G13: S' N2 D1 P M1 G2 R2 S | H13: =1+ISNUMBER(SEARCH("R",F13))+ISNUMBER(SEARCH("G",F13))+ISNUMBER(SEARCH("M",F13))+ISNUMBER(SEARCH("P",F13))+ISNUMBER(SEARCH("D",F13))+ISNUMBER(SEARCH("N",F13)) -> 7 | I13: =1+ISNUMBER(SEARCH("R",G13))+ISNUMBER(SEARCH("G",G13))+ISNUMBER(SEARCH("M",G13))+ISNUMBER(SEARCH("P",G13))+ISNUMBER(SEARCH("D",G13))+ISNUMBER(SEARCH("N",G13)) -> 7 | J13: =IFERROR(CHOOSE(H13-3,"Svarantara","Audava","Shadava","Sampoorna"),"Other") -> Sampoorna | K13: =IFERROR(CHOOSE(I13-3,"Svarantara","Audava","Shadava","Sampoorna"),"Other") -> Sampoorna | L13: =J13&" - "&K13 -> Sampoorna - Sampoorna | M13: No | N13: A - Very common | O13: Your sheet (systematic) | P13: High | Q13: Natabhairavi (parent of Bhairavi) | R13: 20
A14: 13 | B14: Keeravani | C14: Melakarta | D14: 21 | E14: (is a melakarta) | F14: S R2 G2 M1 P D1 N3 S' | G14: S' N3 D1 P M1 G2 R2 S | H14: =1+ISNUMBER(SEARCH("R",F14))+ISNUMBER(SEARCH("G",F14))+ISNUMBER(SEARCH("M",F14))+ISNUMBER(SEARCH("P",F14))+ISNUMBER(SEARCH("D",F14))+ISNUMBER(SEARCH("N",F14)) -> 7 | I14: =1+ISNUMBER(SEARCH("R",G14))+ISNUMBER(SEARCH("G",G14))+ISNUMBER(SEARCH("M",G14))+ISNUMBER(SEARCH("P",G14))+ISNUMBER(SEARCH("D",G14))+ISNUMBER(SEARCH("N",G14)) -> 7 | J14: =IFERROR(CHOOSE(H14-3,"Svarantara","Audava","Shadava","Sampoorna"),"Other") -> Sampoorna | K14: =IFERROR(CHOOSE(I14-3,"Svarantara","Audava","Shadava","Sampoorna"),"Other") -> Sampoorna | L14: =J14&" - "&K14 -> Sampoorna - Sampoorna | M14: No | N14: A - Very common | O14: Your sheet (systematic) | P14: High | R14: 21
A15: 14 | B15: Begada | C15: Janya | D15: 29 | E15: 29 - Dheerasankarabharanam | F15: S G3 R2 G3 M1 P D2 P S' | G15: S' N3 D2 P M1 G3 R2 S | H15: =1+ISNUMBER(SEARCH("R",F15))+ISNUMBER(SEARCH("G",F15))+ISNUMBER(SEARCH("M",F15))+ISNUMBER(SEARCH("P",F15))+ISNUMBER(SEARCH("D",F15))+ISNUMBER(SEARCH("N",F15)) -> 6 | I15: =1+ISNUMBER(SEARCH("R",G15))+ISNUMBER(SEARCH("G",G15))+ISNUMBER(SEARCH("M",G15))+ISNUMBER(SEARCH("P",G15))+ISNUMBER(SEARCH("D",G15))+ISNUMBER(SEARCH("N",G15)) -> 7 | J15: =IFERROR(CHOOSE(H15-3,"Svarantara","Audava","Shadava","Sampoorna"),"Other") -> Shadava | K15: =IFERROR(CHOOSE(I15-3,"Svarantara","Audava","Shadava","Sampoorna"),"Other") -> Sampoorna | L15: =J15&" - "&K15 -> Shadava - Sampoorna | M15: Yes | N15: A - Very common | O15: Wikipedia - List of Janya ragas | P15: High | Q15: Vakra ascent. | R15: 154
A16: 15 | B16: Bilahari | C16: Janya | D16: 29 | E16: 29 - Dheerasankarabharanam | F16: S R2 G3 P D2 S' | G16: S' N3 D2 P M1 G3 R2 S | H16: =1+ISNUMBER(SEARCH("R",F16))+ISNUMBER(SEARCH("G",F16))+ISNUMBER(SEARCH("M",F16))+ISNUMBER(SEARCH("P",F16))+ISNUMBER(SEARCH("D",F16))+ISNUMBER(SEARCH("N",F16)) -> 5 | I16: =1+ISNUMBER(SEARCH("R",G16))+ISNUMBER(SEARCH("G",G16))+ISNUMBER(SEARCH("M",G16))+ISNUMBER(SEARCH("P",G16))+ISNUMBER(SEARCH("D",G16))+ISNUMBER(SEARCH("N",G16)) -> 7 | J16: =IFERROR(CHOOSE(H16-3,"Svarantara","Audava","Shadava","Sampoorna"),"Other") -> Audava | K16: =IFERROR(CHOOSE(I16-3,"Svarantara","Audava","Shadava","Sampoorna"),"Other") -> Sampoorna | L16: =J16&" - "&K16 -> Audava - Sampoorna | M16: No | N16: A - Very common | O16: Your sheet | P16: High | Q16: Bhashanga (N2 anya swara). | R16: 140
A17: 16 | B17: Hamsadhwani | C17: Janya | D17: 29 | E17: 29 - Dheerasankarabharanam | F17: S R2 G3 P N3 S' | G17: S' N3 P G3 R2 S | H17: =1+ISNUMBER(SEARCH("R",F17))+ISNUMBER(SEARCH("G",F17))+ISNUMBER(SEARCH("M",F17))+ISNUMBER(SEARCH("P",F17))+ISNUMBER(SEARCH("D",F17))+ISNUMBER(SEARCH("N",F17)) -> 5 | I17: =1+ISNUMBER(SEARCH("R",G17))+ISNUMBER(SEARCH("G",G17))+ISNUMBER(SEARCH("M",G17))+ISNUMBER(SEARCH("P",G17))+ISNUMBER(SEARCH("D",G17))+ISNUMBER(SEARCH("N",G17)) -> 5 | J17: =IFERROR(CHOOSE(H17-3,"Svarantara","Audava","Shadava","Sampoorna"),"Other") -> Audava | K17: =IFERROR(CHOOSE(I17-3,"Svarantara","Audava","Shadava","Sampoorna"),"Other") -> Audava | L17: =J17&" - "&K17 -> Audava - Audava | M17: No | N17: A - Very common | O17: Your sheet | P17: High | R17: 141
A18: 17 | B18: Saveri | C18: Janya | D18: 15 | E18: 15 - Mayamalavagowla | F18: S R1 M1 P D1 S' | G18: S' N2 D1 P M1 G3 R1 S | H18: =1+ISNUMBER(SEARCH("R",F18))+ISNUMBER(SEARCH("G",F18))+ISNUMBER(SEARCH("M",F18))+ISNUMBER(SEARCH("P",F18))+ISNUMBER(SEARCH("D",F18))+ISNUMBER(SEARCH("N",F18)) -> 5 | I18: =1+ISNUMBER(SEARCH("R",G18))+ISNUMBER(SEARCH("G",G18))+ISNUMBER(SEARCH("M",G18))+ISNUMBER(SEARCH("P",G18))+ISNUMBER(SEARCH("D",G18))+ISNUMBER(SEARCH("N",G18)) -> 7 | J18: =IFERROR(CHOOSE(H18-3,"Svarantara","Audava","Shadava","Sampoorna"),"Other") -> Audava | K18: =IFERROR(CHOOSE(I18-3,"Svarantara","Audava","Shadava","Sampoorna"),"Other") -> Sampoorna | L18: =J18&" - "&K18 -> Audava - Sampoorna | M18: No | N18: A - Very common | O18: Your sheet | P18: High | Q18: Descent uses N2 per your sheet; some sources give N3. | R18: 90
A19: 18 | B19: Madhyamavati | C19: Janya | D19: 22 | E19: 22 - Kharaharapriya | F19: S R2 M1 P N2 S' | G19: S' N2 P M1 R2 S | H19: =1+ISNUMBER(SEARCH("R",F19))+ISNUMBER(SEARCH("G",F19))+ISNUMBER(SEARCH("M",F19))+ISNUMBER(SEARCH("P",F19))+ISNUMBER(SEARCH("D",F19))+ISNUMBER(SEARCH("N",F19)) -> 5 | I19: =1+ISNUMBER(SEARCH("R",G19))+ISNUMBER(SEARCH("G",G19))+ISNUMBER(SEARCH("M",G19))+ISNUMBER(SEARCH("P",G19))+ISNUMBER(SEARCH("D",G19))+ISNUMBER(SEARCH("N",G19)) -> 5 | J19: =IFERROR(CHOOSE(H19-3,"Svarantara","Audava","Shadava","Sampoorna"),"Other") -> Audava | K19: =IFERROR(CHOOSE(I19-3,"Svarantara","Audava","Shadava","Sampoorna"),"Other") -> Audava | L19: =J19&" - "&K19 -> Audava - Audava | M19: No | N19: A - Very common | O19: Your sheet | P19: High | R19: 113
A20: 19 | B20: Anandabhairavi | C20: Janya | D20: 20 | E20: 20 - Natabhairavi | F20: S G2 R2 G2 M1 P D1 P S' | G20: S' N2 D1 P M1 G2 R2 S | H20: =1+ISNUMBER(SEARCH("R",F20))+ISNUMBER(SEARCH("G",F20))+ISNUMBER(SEARCH("M",F20))+ISNUMBER(SEARCH("P",F20))+ISNUMBER(SEARCH("D",F20))+ISNUMBER(SEARCH("N",F20)) -> 6 | I20: =1+ISNUMBER(SEARCH("R",G20))+ISNUMBER(SEARCH("G",G20))+ISNUMBER(SEARCH("M",G20))+ISNUMBER(SEARCH("P",G20))+ISNUMBER(SEARCH("D",G20))+ISNUMBER(SEARCH("N",G20)) -> 7 | J20: =IFERROR(CHOOSE(H20-3,"Svarantara","Audava","Shadava","Sampoorna"),"Other") -> Shadava | K20: =IFERROR(CHOOSE(I20-3,"Svarantara","Audava","Shadava","Sampoorna"),"Other") -> Sampoorna | L20: =J20&" - "&K20 -> Shadava - Sampoorna | M20: Yes | N20: A - Very common | O20: Wikipedia list, adapted to parent 20 | P20: Check | Q20: Vakra; no Nishadam in the ascent. Wikipedia writes D2 (with G3, D1, N3 as anya swaras); the dhaivatam varies by source. | R20: 101
A21: 20 | B21: Hindolam | C21: Janya | D21: 20 | E21: 20 - Natabhairavi | F21: S G2 M1 D1 N2 S' | G21: S' N2 D1 M1 G2 S | H21: =1+ISNUMBER(SEARCH("R",F21))+ISNUMBER(SEARCH("G",F21))+ISNUMBER(SEARCH("M",F21))+ISNUMBER(SEARCH("P",F21))+ISNUMBER(SEARCH("D",F21))+ISNUMBER(SEARCH("N",F21)) -> 5 | I21: =1+ISNUMBER(SEARCH("R",G21))+ISNUMBER(SEARCH("G",G21))+ISNUMBER(SEARCH("M",G21))+ISNUMBER(SEARCH("P",G21))+ISNUMBER(SEARCH("D",G21))+ISNUMBER(SEARCH("N",G21)) -> 5 | J21: =IFERROR(CHOOSE(H21-3,"Svarantara","Audava","Shadava","Sampoorna"),"Other") -> Audava | K21: =IFERROR(CHOOSE(I21-3,"Svarantara","Audava","Shadava","Sampoorna"),"Other") -> Audava | L21: =J21&" - "&K21 -> Audava - Audava | M21: No | N21: A - Very common | O21: Your sheet | P21: High | R21: 102
A22: 21 | B22: Sahana | C22: Janya | D22: 28 | E22: 28 - Harikambhoji | F22: S R2 G3 M1 P M1 D2 N2 S' | G22: S' N2 D2 P M1 G3 M1 R2 G3 R2 S | H22: =1+ISNUMBER(SEARCH("R",F22))+ISNUMBER(SEARCH("G",F22))+ISNUMBER(SEARCH("M",F22))+ISNUMBER(SEARCH("P",F22))+ISNUMBER(SEARCH("D",F22))+ISNUMBER(SEARCH("N",F22)) -> 7 | I22: =1+ISNUMBER(SEARCH("R",G22))+ISNUMBER(SEARCH("G",G22))+ISNUMBER(SEARCH("M",G22))+ISNUMBER(SEARCH("P",G22))+ISNUMBER(SEARCH("D",G22))+ISNUMBER(SEARCH("N",G22)) -> 7 | J22: =IFERROR(CHOOSE(H22-3,"Svarantara","Audava","Shadava","Sampoorna"),"Other") -> Sampoorna | K22: =IFERROR(CHOOSE(I22-3,"Svarantara","Audava","Shadava","Sampoorna"),"Other") -> Sampoorna | L22: =J22&" - "&K22 -> Sampoorna - Sampoorna | M22: Yes | N22: A - Very common | O22: Wikipedia list (simplified) | P22: High | Q22: Vakra; bhashanga (G3 anya swara). | R22: 126
A23: 22 | B23: Kapi | C23: Janya | D23: 22 | E23: 22 - Kharaharapriya | F23: S R2 M1 P N3 S' | G23: S' N2 D2 N2 P M1 G2 R2 S | H23: =1+ISNUMBER(SEARCH("R",F23))+ISNUMBER(SEARCH("G",F23))+ISNUMBER(SEARCH("M",F23))+ISNUMBER(SEARCH("P",F23))+ISNUMBER(SEARCH("D",F23))+ISNUMBER(SEARCH("N",F23)) -> 5 | I23: =1+ISNUMBER(SEARCH("R",G23))+ISNUMBER(SEARCH("G",G23))+ISNUMBER(SEARCH("M",G23))+ISNUMBER(SEARCH("P",G23))+ISNUMBER(SEARCH("D",G23))+ISNUMBER(SEARCH("N",G23)) -> 7 | J23: =IFERROR(CHOOSE(H23-3,"Svarantara","Audava","Shadava","Sampoorna"),"Other") -> Audava | K23: =IFERROR(CHOOSE(I23-3,"Svarantara","Audava","Shadava","Sampoorna"),"Other") -> Sampoorna | L23: =J23&" - "&K23 -> Audava - Sampoorna | M23: Yes | N23: A - Very common | O23: Wikipedia - List of Janya ragas | P23: High | Q23: Bhashanga (N3 in ascent); vakra descent. | R23: 111
A24: 23 | B24: Abhogi | C24: Janya | D24: 22 | E24: 22 - Kharaharapriya | F24: S R2 G2 M1 D2 S' | G24: S' D2 M1 G2 R2 S | H24: =1+ISNUMBER(SEARCH("R",F24))+ISNUMBER(SEARCH("G",F24))+ISNUMBER(SEARCH("M",F24))+ISNUMBER(SEARCH("P",F24))+ISNUMBER(SEARCH("D",F24))+ISNUMBER(SEARCH("N",F24)) -> 5 | I24: =1+ISNUMBER(SEARCH("R",G24))+ISNUMBER(SEARCH("G",G24))+ISNUMBER(SEARCH("M",G24))+ISNUMBER(SEARCH("P",G24))+ISNUMBER(SEARCH("D",G24))+ISNUMBER(SEARCH("N",G24)) -> 5 | J24: =IFERROR(CHOOSE(H24-3,"Svarantara","Audava","Shadava","Sampoorna"),"Other") -> Audava | K24: =IFERROR(CHOOSE(I24-3,"Svarantara","Audava","Shadava","Sampoorna"),"Other") -> Audava | L24: =J24&" - "&K24 -> Audava - Audava | M24: No | N24: A - Very common | O24: Your sheet | P24: High | R24: 120
A25: 24 | B25: Arabhi | C25: Janya | D25: 29 | E25: 29 - Dheerasankarabharanam | F25: S R2 M1 P D2 S' | G25: S' N3 D2 P M1 G3 R2 S | H25: =1+ISNUMBER(SEARCH("R",F25))+ISNUMBER(SEARCH("G",F25))+ISNUMBER(SEARCH("M",F25))+ISNUMBER(SEARCH("P",F25))+ISNUMBER(SEARCH("D",F25))+ISNUMBER(SEARCH("N",F25)) -> 5 | I25: =1+ISNUMBER(SEARCH("R",G25))+ISNUMBER(SEARCH("G",G25))+ISNUMBER(SEARCH("M",G25))+ISNUMBER(SEARCH("P",G25))+ISNUMBER(SEARCH("D",G25))+ISNUMBER(SEARCH("N",G25)) -> 7 | J25: =IFERROR(CHOOSE(H25-3,"Svarantara","Audava","Shadava","Sampoorna"),"Other") -> Audava | K25: =IFERROR(CHOOSE(I25-3,"Svarantara","Audava","Shadava","Sampoorna"),"Other") -> Sampoorna | L25: =J25&" - "&K25 -> Audava - Sampoorna | M25: No | N25: A - Very common | O25: Your sheet | P25: High | Q25: Vakra phrases in practice. | R25: 142
A26: 25 | B26: Atana | C26: Janya | D26: 29 | E26: 29 - Dheerasankarabharanam | F26: S R2 M1 P N2 S' | G26: S' N2 D2 P M1 G2 M1 R2 S | H26: =1+ISNUMBER(SEARCH("R",F26))+ISNUMBER(SEARCH("G",F26))+ISNUMBER(SEARCH("M",F26))+ISNUMBER(SEARCH("P",F26))+ISNUMBER(SEARCH("D",F26))+ISNUMBER(SEARCH("N",F26)) -> 5 | I26: =1+ISNUMBER(SEARCH("R",G26))+ISNUMBER(SEARCH("G",G26))+ISNUMBER(SEARCH("M",G26))+ISNUMBER(SEARCH("P",G26))+ISNUMBER(SEARCH("D",G26))+ISNUMBER(SEARCH("N",G26)) -> 7 | J26: =IFERROR(CHOOSE(H26-3,"Svarantara","Audava","Shadava","Sampoorna"),"Other") -> Audava | K26: =IFERROR(CHOOSE(I26-3,"Svarantara","Audava","Shadava","Sampoorna"),"Other") -> Sampoorna | L26: =J26&" - "&K26 -> Audava - Sampoorna | M26: Yes | N26: A - Very common | O26: Wikipedia - List of Janya ragas | P26: High | Q26: Bhashanga: G2 and N2 are anya swaras. | R26: 144
A27: 26 | B27: Behag | C27: Janya | D27: 29 | E27: 29 - Dheerasankarabharanam | F27: S G3 M1 P N3 D2 N3 S' | G27: S' N3 D2 P M1 G3 R2 S | H27: =1+ISNUMBER(SEARCH("R",F27))+ISNUMBER(SEARCH("G",F27))+ISNUMBER(SEARCH("M",F27))+ISNUMBER(SEARCH("P",F27))+ISNUMBER(SEARCH("D",F27))+ISNUMBER(SEARCH("N",F27)) -> 6 | I27: =1+ISNUMBER(SEARCH("R",G27))+ISNUMBER(SEARCH("G",G27))+ISNUMBER(SEARCH("M",G27))+ISNUMBER(SEARCH("P",G27))+ISNUMBER(SEARCH("D",G27))+ISNUMBER(SEARCH("N",G27)) -> 7 | J27: =IFERROR(CHOOSE(H27-3,"Svarantara","Audava","Shadava","Sampoorna"),"Other") -> Shadava | K27: =IFERROR(CHOOSE(I27-3,"Svarantara","Audava","Shadava","Sampoorna"),"Other") -> Sampoorna | L27: =J27&" - "&K27 -> Shadava - Sampoorna | M27: Yes | N27: A - Very common | O27: Wikipedia - List of Janya ragas | P27: High | Q27: Bhashanga (M2 and N2 anya swaras); vakra ascent. | R27: 148
A28: 27 | B28: Sriranjani | C28: Janya | D28: 22 | E28: 22 - Kharaharapriya | F28: S R2 G2 M1 D2 N2 S' | G28: S' N2 D2 M1 G2 R2 S | H28: =1+ISNUMBER(SEARCH("R",F28))+ISNUMBER(SEARCH("G",F28))+ISNUMBER(SEARCH("M",F28))+ISNUMBER(SEARCH("P",F28))+ISNUMBER(SEARCH("D",F28))+ISNUMBER(SEARCH("N",F28)) -> 6 | I28: =1+ISNUMBER(SEARCH("R",G28))+ISNUMBER(SEARCH("G",G28))+ISNUMBER(SEARCH("M",G28))+ISNUMBER(SEARCH("P",G28))+ISNUMBER(SEARCH("D",G28))+ISNUMBER(SEARCH("N",G28)) -> 6 | J28: =IFERROR(CHOOSE(H28-3,"Svarantara","Audava","Shadava","Sampoorna"),"Other") -> Shadava | K28: =IFERROR(CHOOSE(I28-3,"Svarantara","Audava","Shadava","Sampoorna"),"Other") -> Shadava | L28: =J28&" - "&K28 -> Shadava - Shadava | M28: No | N28: A - Very common | O28: Your sheet | P28: High | R28: 115
A29: 28 | B29: Sriragam | C29: Janya | D29: 22 | E29: 22 - Kharaharapriya | F29: S R2 M1 P N2 S' | G29: S' N2 P D2 N2 P M1 R2 G2 R2 S | H29: =1+ISNUMBER(SEARCH("R",F29))+ISNUMBER(SEARCH("G",F29))+ISNUMBER(SEARCH("M",F29))+ISNUMBER(SEARCH("P",F29))+ISNUMBER(SEARCH("D",F29))+ISNUMBER(SEARCH("N",F29)) -> 5 | I29: =1+ISNUMBER(SEARCH("R",G29))+ISNUMBER(SEARCH("G",G29))+ISNUMBER(SEARCH("M",G29))+ISNUMBER(SEARCH("P",G29))+ISNUMBER(SEARCH("D",G29))+ISNUMBER(SEARCH("N",G29)) -> 7 | J29: =IFERROR(CHOOSE(H29-3,"Svarantara","Audava","Shadava","Sampoorna"),"Other") -> Audava | K29: =IFERROR(CHOOSE(I29-3,"Svarantara","Audava","Shadava","Sampoorna"),"Other") -> Sampoorna | L29: =J29&" - "&K29 -> Audava - Sampoorna | M29: Yes | N29: A - Very common | O29: Wikipedia - List of Janya ragas | P29: High | Q29: Vakra descent. | R29: 110
A30: 29 | B30: Dhanyasi | C30: Janya | D30: 8 | E30: 8 - Hanumatodi | F30: S G2 M1 P N2 S' | G30: S' N2 D1 P M1 G2 R1 S | H30: =1+ISNUMBER(SEARCH("R",F30))+ISNUMBER(SEARCH("G",F30))+ISNUMBER(SEARCH("M",F30))+ISNUMBER(SEARCH("P",F30))+ISNUMBER(SEARCH("D",F30))+ISNUMBER(SEARCH("N",F30)) -> 5 | I30: =1+ISNUMBER(SEARCH("R",G30))+ISNUMBER(SEARCH("G",G30))+ISNUMBER(SEARCH("M",G30))+ISNUMBER(SEARCH("P",G30))+ISNUMBER(SEARCH("D",G30))+ISNUMBER(SEARCH("N",G30)) -> 7 | J30: =IFERROR(CHOOSE(H30-3,"Svarantara","Audava","Shadava","Sampoorna"),"Other") -> Audava | K30: =IFERROR(CHOOSE(I30-3,"Svarantara","Audava","Shadava","Sampoorna"),"Other") -> Sampoorna | L30: =J30&" - "&K30 -> Audava - Sampoorna | M30: No | N30: A - Very common | O30: Wikipedia - raga article | P30: Check | Q30: Your sheet's avarohanam omits D1 (S' N2 P M1 G2 R1 S), which would make it Audava-Shadava. Wikipedia gives D1 and R1 in the descent (audava-sampurna). Confirm with the expert. | R30: 73
A31: 30 | B31: Abheri | C31: Janya | D31: 22 | E31: 22 - Kharaharapriya | F31: S G2 M1 P N2 S' | G31: S' N2 P M1 G2 R2 S | H31: =1+ISNUMBER(SEARCH("R",F31))+ISNUMBER(SEARCH("G",F31))+ISNUMBER(SEARCH("M",F31))+ISNUMBER(SEARCH("P",F31))+ISNUMBER(SEARCH("D",F31))+ISNUMBER(SEARCH("N",F31)) -> 5 | I31: =1+ISNUMBER(SEARCH("R",G31))+ISNUMBER(SEARCH("G",G31))+ISNUMBER(SEARCH("M",G31))+ISNUMBER(SEARCH("P",G31))+ISNUMBER(SEARCH("D",G31))+ISNUMBER(SEARCH("N",G31)) -> 6 | J31: =IFERROR(CHOOSE(H31-3,"Svarantara","Audava","Shadava","Sampoorna"),"Other") -> Audava | K31: =IFERROR(CHOOSE(I31-3,"Svarantara","Audava","Shadava","Sampoorna"),"Other") -> Shadava | L31: =J31&" - "&K31 -> Audava - Shadava | M31: No | N31: A - Very common | O31: Your sheet | P31: High | R31: 107
A32: 31 | B32: Mukhari | C32: Janya | D32: 22 | E32: 22 - Kharaharapriya | F32: S R2 M1 P N2 D2 S' | G32: S' N2 D1 P M1 G2 R2 S | H32: =1+ISNUMBER(SEARCH("R",F32))+ISNUMBER(SEARCH("G",F32))+ISNUMBER(SEARCH("M",F32))+ISNUMBER(SEARCH("P",F32))+ISNUMBER(SEARCH("D",F32))+ISNUMBER(SEARCH("N",F32)) -> 6 | I32: =1+ISNUMBER(SEARCH("R",G32))+ISNUMBER(SEARCH("G",G32))+ISNUMBER(SEARCH("M",G32))+ISNUMBER(SEARCH("P",G32))+ISNUMBER(SEARCH("D",G32))+ISNUMBER(SEARCH("N",G32)) -> 7 | J32: =IFERROR(CHOOSE(H32-3,"Svarantara","Audava","Shadava","Sampoorna"),"Other") -> Shadava | K32: =IFERROR(CHOOSE(I32-3,"Svarantara","Audava","Shadava","Sampoorna"),"Other") -> Sampoorna | L32: =J32&" - "&K32 -> Shadava - Sampoorna | M32: Yes | N32: A - Very common | O32: Wikipedia - List of Janya ragas | P32: Check | Q32: Vakra ascent. Sources differ on whether Dha is in the ascent; D1 in the descent is an anya swara. | R32: 108
A33: 32 | B33: Kedaragowla | C33: Janya | D33: 28 | E33: 28 - Harikambhoji | F33: S R2 M1 P N2 S' | G33: S' N2 D2 P M1 G3 R2 S | H33: =1+ISNUMBER(SEARCH("R",F33))+ISNUMBER(SEARCH("G",F33))+ISNUMBER(SEARCH("M",F33))+ISNUMBER(SEARCH("P",F33))+ISNUMBER(SEARCH("D",F33))+ISNUMBER(SEARCH("N",F33)) -> 5 | I33: =1+ISNUMBER(SEARCH("R",G33))+ISNUMBER(SEARCH("G",G33))+ISNUMBER(SEARCH("M",G33))+ISNUMBER(SEARCH("P",G33))+ISNUMBER(SEARCH("D",G33))+ISNUMBER(SEARCH("N",G33)) -> 7 | J33: =IFERROR(CHOOSE(H33-3,"Svarantara","Audava","Shadava","Sampoorna"),"Other") -> Audava | K33: =IFERROR(CHOOSE(I33-3,"Svarantara","Audava","Shadava","Sampoorna"),"Other") -> Sampoorna | L33: =J33&" - "&K33 -> Audava - Sampoorna | M33: No | N33: A - Very common | O33: Wikipedia - List of Janya ragas | P33: High | R33: 125
A34: 33 | B34: Khamas | C34: Janya | D34: 28 | E34: 28 - Harikambhoji | F34: S M1 G3 M1 P D2 N3 S' | G34: S' N2 D2 P M1 G3 R2 S | H34: =1+ISNUMBER(SEARCH("R",F34))+ISNUMBER(SEARCH("G",F34))+ISNUMBER(SEARCH("M",F34))+ISNUMBER(SEARCH("P",F34))+ISNUMBER(SEARCH("D",F34))+ISNUMBER(SEARCH("N",F34)) -> 6 | I34: =1+ISNUMBER(SEARCH("R",G34))+ISNUMBER(SEARCH("G",G34))+ISNUMBER(SEARCH("M",G34))+ISNUMBER(SEARCH("P",G34))+ISNUMBER(SEARCH("D",G34))+ISNUMBER(SEARCH("N",G34)) -> 7 | J34: =IFERROR(CHOOSE(H34-3,"Svarantara","Audava","Shadava","Sampoorna"),"Other") -> Shadava | K34: =IFERROR(CHOOSE(I34-3,"Svarantara","Audava","Shadava","Sampoorna"),"Other") -> Sampoorna | L34: =J34&" - "&K34 -> Shadava - Sampoorna | M34: Yes | N34: A - Very common | O34: Wikipedia - List of Janya ragas | P34: High | Q34: Bhashanga (N3 in ascent); vakra ascent. | R34: 124
A35: 34 | B35: Shivaranjani | C35: Janya | D35: 22 | E35: 22 - Kharaharapriya | F35: S R2 G2 P D2 S' | G35: S' D2 P G2 R2 S | H35: =1+ISNUMBER(SEARCH("R",F35))+ISNUMBER(SEARCH("G",F35))+ISNUMBER(SEARCH("M",F35))+ISNUMBER(SEARCH("P",F35))+ISNUMBER(SEARCH("D",F35))+ISNUMBER(SEARCH("N",F35)) -> 5 | I35: =1+ISNUMBER(SEARCH("R",G35))+ISNUMBER(SEARCH("G",G35))+ISNUMBER(SEARCH("M",G35))+ISNUMBER(SEARCH("P",G35))+ISNUMBER(SEARCH("D",G35))+ISNUMBER(SEARCH("N",G35)) -> 5 | J35: =IFERROR(CHOOSE(H35-3,"Svarantara","Audava","Shadava","Sampoorna"),"Other") -> Audava | K35: =IFERROR(CHOOSE(I35-3,"Svarantara","Audava","Shadava","Sampoorna"),"Other") -> Audava | L35: =J35&" - "&K35 -> Audava - Audava | M35: No | N35: A - Very common | O35: Wikipedia - List of Janya ragas | P35: High | R35: 117
A36: 35 | B36: Malahari | C36: Janya | D36: 15 | E36: 15 - Mayamalavagowla | F36: S R1 M1 P D1 S' | G36: S' D1 P M1 G3 R1 S | H36: =1+ISNUMBER(SEARCH("R",F36))+ISNUMBER(SEARCH("G",F36))+ISNUMBER(SEARCH("M",F36))+ISNUMBER(SEARCH("P",F36))+ISNUMBER(SEARCH("D",F36))+ISNUMBER(SEARCH("N",F36)) -> 5 | I36: =1+ISNUMBER(SEARCH("R",G36))+ISNUMBER(SEARCH("G",G36))+ISNUMBER(SEARCH("M",G36))+ISNUMBER(SEARCH("P",G36))+ISNUMBER(SEARCH("D",G36))+ISNUMBER(SEARCH("N",G36)) -> 6 | J36: =IFERROR(CHOOSE(H36-3,"Svarantara","Audava","Shadava","Sampoorna"),"Other") -> Audava | K36: =IFERROR(CHOOSE(I36-3,"Svarantara","Audava","Shadava","Sampoorna"),"Other") -> Shadava | L36: =J36&" - "&K36 -> Audava - Shadava | M36: No | N36: A - Very common | O36: Your sheet | P36: High | R36: 85
A37: 36 | B37: Punnagavarali | C37: Janya | D37: 8 | E37: 8 - Hanumatodi | F37: N2 S R1 G2 M1 P D1 N2 | G37: N2 D1 P M1 G2 R1 S N2 | H37: =1+ISNUMBER(SEARCH("R",F37))+ISNUMBER(SEARCH("G",F37))+ISNUMBER(SEARCH("M",F37))+ISNUMBER(SEARCH("P",F37))+ISNUMBER(SEARCH("D",F37))+ISNUMBER(SEARCH("N",F37)) -> 7 | I37: =1+ISNUMBER(SEARCH("R",G37))+ISNUMBER(SEARCH("G",G37))+ISNUMBER(SEARCH("M",G37))+ISNUMBER(SEARCH("P",G37))+ISNUMBER(SEARCH("D",G37))+ISNUMBER(SEARCH("N",G37)) -> 7 | J37: =IFERROR(CHOOSE(H37-3,"Svarantara","Audava","Shadava","Sampoorna"),"Other") -> Sampoorna | K37: =IFERROR(CHOOSE(I37-3,"Svarantara","Audava","Shadava","Sampoorna"),"Other") -> Sampoorna | L37: =J37&" - "&K37 -> Sampoorna - Sampoorna | M37: No | N37: A - Very common | O37: Wikipedia - raga article | P37: High | Q37: Nishadantya: sung N2 to N2 in one octave (no upper Sa). R2 sometimes used in the ascent. | R37: 76
A38: 37 | B38: Varali | C38: Janya | D38: 39 | E38: 39 - Jhalavarali | F38: S G1 R1 G1 M2 P D1 N3 S' | G38: S' N3 D1 P M2 G1 R1 S | H38: =1+ISNUMBER(SEARCH("R",F38))+ISNUMBER(SEARCH("G",F38))+ISNUMBER(SEARCH("M",F38))+ISNUMBER(SEARCH("P",F38))+ISNUMBER(SEARCH("D",F38))+ISNUMBER(SEARCH("N",F38)) -> 7 | I38: =1+ISNUMBER(SEARCH("R",G38))+ISNUMBER(SEARCH("G",G38))+ISNUMBER(SEARCH("M",G38))+ISNUMBER(SEARCH("P",G38))+ISNUMBER(SEARCH("D",G38))+ISNUMBER(SEARCH("N",G38)) -> 7 | J38: =IFERROR(CHOOSE(H38-3,"Svarantara","Audava","Shadava","Sampoorna"),"Other") -> Sampoorna | K38: =IFERROR(CHOOSE(I38-3,"Svarantara","Audava","Shadava","Sampoorna"),"Other") -> Sampoorna | L38: =J38&" - "&K38 -> Sampoorna - Sampoorna | M38: Yes | N38: A - Very common | O38: Wikipedia - List of Janya ragas | P38: Check | Q38: Vakra ascent, as written in Wikipedia's list. Confirm with the expert. | R38: 162
A39: 38 | B39: Asaveri | C39: Janya | D39: 8 | E39: 8 - Hanumatodi | F39: S R1 M1 P D1 S' | G39: S' N2 S P D1 M1 P R2 G2 R1 S | H39: =1+ISNUMBER(SEARCH("R",F39))+ISNUMBER(SEARCH("G",F39))+ISNUMBER(SEARCH("M",F39))+ISNUMBER(SEARCH("P",F39))+ISNUMBER(SEARCH("D",F39))+ISNUMBER(SEARCH("N",F39)) -> 5 | I39: =1+ISNUMBER(SEARCH("R",G39))+ISNUMBER(SEARCH("G",G39))+ISNUMBER(SEARCH("M",G39))+ISNUMBER(SEARCH("P",G39))+ISNUMBER(SEARCH("D",G39))+ISNUMBER(SEARCH("N",G39)) -> 7 | J39: =IFERROR(CHOOSE(H39-3,"Svarantara","Audava","Shadava","Sampoorna"),"Other") -> Audava | K39: =IFERROR(CHOOSE(I39-3,"Svarantara","Audava","Shadava","Sampoorna"),"Other") -> Sampoorna | L39: =J39&" - "&K39 -> Audava - Sampoorna | M39: Yes | N39: A - Very common | O39: Wikipedia - raga article | P39: High | Q39: Vakra descent; bhashanga (R2 is an anya swara). | R39: 74
A40: 39 | B40: Simhendramadhyamam | C40: Melakarta | D40: 57 | E40: (is a melakarta) | F40: S R2 G2 M2 P D1 N3 S' | G40: S' N3 D1 P M2 G2 R2 S | H40: =1+ISNUMBER(SEARCH("R",F40))+ISNUMBER(SEARCH("G",F40))+ISNUMBER(SEARCH("M",F40))+ISNUMBER(SEARCH("P",F40))+ISNUMBER(SEARCH("D",F40))+ISNUMBER(SEARCH("N",F40)) -> 7 | I40: =1+ISNUMBER(SEARCH("R",G40))+ISNUMBER(SEARCH("G",G40))+ISNUMBER(SEARCH("M",G40))+ISNUMBER(SEARCH("P",G40))+ISNUMBER(SEARCH("D",G40))+ISNUMBER(SEARCH("N",G40)) -> 7 | J40: =IFERROR(CHOOSE(H40-3,"Svarantara","Audava","Shadava","Sampoorna"),"Other") -> Sampoorna | K40: =IFERROR(CHOOSE(I40-3,"Svarantara","Audava","Shadava","Sampoorna"),"Other") -> Sampoorna | L40: =J40&" - "&K40 -> Sampoorna - Sampoorna | M40: No | N40: B - Common | O40: Your sheet (systematic) | P40: High | R40: 57
...

Sheet Summary
A1: Summary - Top 100 ragas
A3: Raga class matrix (rows = arohanam, columns = avarohanam)
A4: Arohanam \ Avarohanam | B4: Sampoorna | C4: Shadava | D4: Audava
A5: Sampoorna | B5: =COUNTIFS('Top 100 Ragas'!$J$2:$J$101,$A5,'Top 100 Ragas'!$K$2:$K$101,B$4) -> 38 | C5: =COUNTIFS('Top 100 Ragas'!$J$2:$J$101,$A5,'Top 100 Ragas'!$K$2:$K$101,C$4) -> 1 | D5: =COUNTIFS('Top 100 Ragas'!$J$2:$J$101,$A5,'Top 100 Ragas'!$K$2:$K$101,D$4) -> 0
A6: Shadava | B6: =COUNTIFS('Top 100 Ragas'!$J$2:$J$101,$A6,'Top 100 Ragas'!$K$2:$K$101,B$4) -> 15 | C6: =COUNTIFS('Top 100 Ragas'!$J$2:$J$101,$A6,'Top 100 Ragas'!$K$2:$K$101,C$4) -> 7 | D6: =COUNTIFS('Top 100 Ragas'!$J$2:$J$101,$A6,'Top 100 Ragas'!$K$2:$K$101,D$4) -> 0
A7: Audava | B7: =COUNTIFS('Top 100 Ragas'!$J$2:$J$101,$A7,'Top 100 Ragas'!$K$2:$K$101,B$4) -> 17 | C7: =COUNTIFS('Top 100 Ragas'!$J$2:$J$101,$A7,'Top 100 Ragas'!$K$2:$K$101,C$4) -> 8 | D7: =COUNTIFS('Top 100 Ragas'!$J$2:$J$101,$A7,'Top 100 Ragas'!$K$2:$K$101,D$4) -> 14
A8: Total (classified) | B8: =SUM(B5:D7) -> 100
A9: Other / Svarantara | B9: =COUNTA('Top 100 Ragas'!$B$2:$B$101)-B8 -> 0
A11: Other breakdowns
A12: Melakarta (always Sampoorna - Sampoorna) | B12: =COUNTIF('Top 100 Ragas'!$C$2:$C$101,"Melakarta") -> 28
A13: Janya | B13: =COUNTIF('Top 100 Ragas'!$C$2:$C$101,"Janya") -> 72
A14: Pentatonic both ways (Audava - Audava) | B14: =COUNTIFS('Top 100 Ragas'!$J$2:$J$101,"Audava",'Top 100 Ragas'!$K$2:$K$101,"Audava") -> 14
A15: Vakra (zigzag note order in written scale) | B15: =COUNTIF('Top 100 Ragas'!$M$2:$M$101,"Yes") -> 33
A16: Band A - Very common | B16: =COUNTIF('Top 100 Ragas'!$N$2:$N$101,"A - Very common") -> 38
A17: Band B - Common | B17: =COUNTIF('Top 100 Ragas'!$N$2:$N$101,"B - Common") -> 39
A18: Band C - Less common | B18: =COUNTIF('Top 100 Ragas'!$N$2:$N$101,"C - Less common") -> 23
A19: Confidence = Check (needs expert review) | B19: =COUNTIF('Top 100 Ragas'!$P$2:$P$101,"Check") -> 30
A22: Legend
A23: Sampoorna | B23: All 7 swaras (S R G M P D N) in that direction.
A24: Shadava | B24: 6 swaras in that direction (one swara omitted).
A25: Audava | B25: 5 swaras - the pentatonic ragas.
A26: Svarantara | B26: 4 swaras (none in this list).
A27: Raga class | B27: Arohanam class - Avarohanam class, e.g. "Audava - Sampoorna" = 5 notes up, 7 notes down.
A28: Vakra | B28: The written scale zigzags (a note is repeated or the order reverses) in the ascent or descent.
A29: Counting rule | B29: Swaras are counted by letter (R, G, M, P, D, N plus Sa), so M1 and M2 together count once. Anya swaras do not add a new swara unless the letter is new.

Sheet Notes
A1: How this list was made
A2: 1. Your sheet has 170 ragas but no usage-frequency data, so "most used" is a judgment call: your Pilot tier column plus how often each raga appears in the concert repertoire. Rank is approximate within each usage band.
A3: 2. Melakartas: scales come straight from your sheet. Janyas: scales come from your sheet where filled, otherwise from Wikipedia's List of Janya ragas (or the raga's own article). See the "Scale source" column.
A4: 3. Swara counts and the class columns are formulas that read the Arohanam / Avarohanam text, so if you correct a scale the class updates. The Vakra flag is a fixed value worked out from the scale as written here.
A5: 4. Rows marked "Check" in the Confidence column have conflicting sources or a parent mapping that differs from your sheet. Per your golden rule 4, every row still needs the expert to review it before it is used as ground truth.
A7: Differences found against your sheet
A8: - Dhanyasi: your avarohanam omits D1; Wikipedia includes it (changes the class from Audava-Shadava to Audava-Sampoorna).
A9: - Revagupti: your scale (S R1 M1 P D1 S') differs from Wikipedia's list (which has G3 instead of M1).
A10: - Saveri: your descent has N2; some sources give N3. Class is unaffected.
A11: - Parent mapping differs from your sheet for: Brindavana Saranga, Karnataka Behag, Salagabhairavi, Jayamanohari, Kannadagowla, Devamanohari, Vasantabhairavi, Valaji, Sindhu Ramakriya, Gurjari, Kokiladhwani, Narayanagowla (see each row's notes).
A13: Notation: R1/R2/R3, G1/G2/G3, D1/D2/D3, N1/N2/N3, M1/M2; S' = upper Sa. Ragas that are nishadantya (Punnagavarali, Nadanamakriya) are written N to N in one octave.
